[34m[1mwandb[39m[22m: [32m[41mERROR[39m[49m Attempted to fetch artifact without alias (e.g. "<artifact_name>:v3" or "<artifact_name>:latest")
Traceback (most recent call last):
  File "/home/raju/anaconda3/envs/mlflow-cc062a63ecfa81c4fe49a511de5aabce12db6f34/lib/python3.10/site-packages/wandb/apis/public.py", line 5062, in _load
    response = self.client.execute(
  File "/home/raju/anaconda3/envs/mlflow-cc062a63ecfa81c4fe49a511de5aabce12db6f34/lib/python3.10/site-packages/wandb/sdk/lib/retry.py", line 212, in wrapped_fn
    return retrier(*args, **kargs)
  File "/home/raju/anaconda3/envs/mlflow-cc062a63ecfa81c4fe49a511de5aabce12db6f34/lib/python3.10/site-packages/wandb/sdk/lib/retry.py", line 131, in __call__
    result = self._call_fn(*args, **kwargs)
  File "/home/raju/anaconda3/envs/mlflow-cc062a63ecfa81c4fe49a511de5aabce12db6f34/lib/python3.10/site-packages/wandb/apis/public.py", line 251, in execute
    return self._client.execute(*args, **kwargs)
  File "/home/raju/anaconda3/envs/mlflow-cc062a63ecfa81c4fe49a511de5aabce12db6f34/lib/python3.10/site-packages/wandb/vendor/gql-0.2.0/wandb_gql/client.py", line 52, in execute
    result = self._get_result(document, *args, **kwargs)
  File "/home/raju/anaconda3/envs/mlflow-cc062a63ecfa81c4fe49a511de5aabce12db6f34/lib/python3.10/site-packages/wandb/vendor/gql-0.2.0/wandb_gql/client.py", line 60, in _get_result
    return self.transport.execute(document, *args, **kwargs)
  File "/home/raju/anaconda3/envs/mlflow-cc062a63ecfa81c4fe49a511de5aabce12db6f34/lib/python3.10/site-packages/wandb/vendor/gql-0.2.0/wandb_gql/transport/requests.py", line 39, in execute
    request.raise_for_status()
  File "/home/raju/anaconda3/envs/mlflow-cc062a63ecfa81c4fe49a511de5aabce12db6f34/lib/python3.10/site-packages/requests/models.py", line 1021, in raise_for_status
    raise HTTPError(http_error_msg, response=self)
requests.exceptions.HTTPError: 400 Client Error: Bad Request for url: https://api.wandb.ai/graphql
During handling of the above exception, another exception occurred:
Traceback (most recent call last):
  File "/home/raju/anaconda3/envs/mlflow-cc062a63ecfa81c4fe49a511de5aabce12db6f34/lib/python3.10/site-packages/wandb/apis/normalize.py", line 25, in wrapper
    return func(*args, **kwargs)
  File "/home/raju/anaconda3/envs/mlflow-cc062a63ecfa81c4fe49a511de5aabce12db6f34/lib/python3.10/site-packages/wandb/apis/public.py", line 957, in artifact
    artifact = Artifact(self.client, entity, project, artifact_name)
  File "/home/raju/anaconda3/envs/mlflow-cc062a63ecfa81c4fe49a511de5aabce12db6f34/lib/python3.10/site-packages/wandb/apis/public.py", line 4355, in __init__
    self._load()
  File "/home/raju/anaconda3/envs/mlflow-cc062a63ecfa81c4fe49a511de5aabce12db6f34/lib/python3.10/site-packages/wandb/apis/public.py", line 5074, in _load
    raise ValueError(
ValueError: Attempted to fetch artifact without alias (e.g. "<artifact_name>:v3" or "<artifact_name>:latest")
During handling of the above exception, another exception occurred:
Traceback (most recent call last):
  File "/home/raju/Desktop/udacity/Mlops/build-ml-pipeline-for-short-term-rental-prices/src/train_random_forest/run.py", line 302, in <module>
    go(args)
  File "/home/raju/Desktop/udacity/Mlops/build-ml-pipeline-for-short-term-rental-prices/src/train_random_forest/run.py", line 57, in go
    trainval_local_path = run.use_artifact(args.trainval_artifact).file()
  File "/home/raju/anaconda3/envs/mlflow-cc062a63ecfa81c4fe49a511de5aabce12db6f34/lib/python3.10/site-packages/wandb/sdk/wandb_run.py", line 333, in wrapper
    return func(self, *args, **kwargs)
  File "/home/raju/anaconda3/envs/mlflow-cc062a63ecfa81c4fe49a511de5aabce12db6f34/lib/python3.10/site-packages/wandb/sdk/wandb_run.py", line 2625, in use_artifact
    artifact = public_api.artifact(type=type, name=name)
  File "/home/raju/anaconda3/envs/mlflow-cc062a63ecfa81c4fe49a511de5aabce12db6f34/lib/python3.10/site-packages/wandb/apis/normalize.py", line 65, in wrapper
    raise CommError(message, err).with_traceback(sys.exc_info()[2])
  File "/home/raju/anaconda3/envs/mlflow-cc062a63ecfa81c4fe49a511de5aabce12db6f34/lib/python3.10/site-packages/wandb/apis/normalize.py", line 25, in wrapper
    return func(*args, **kwargs)
  File "/home/raju/anaconda3/envs/mlflow-cc062a63ecfa81c4fe49a511de5aabce12db6f34/lib/python3.10/site-packages/wandb/apis/public.py", line 957, in artifact
    artifact = Artifact(self.client, entity, project, artifact_name)
  File "/home/raju/anaconda3/envs/mlflow-cc062a63ecfa81c4fe49a511de5aabce12db6f34/lib/python3.10/site-packages/wandb/apis/public.py", line 4355, in __init__
    self._load()
  File "/home/raju/anaconda3/envs/mlflow-cc062a63ecfa81c4fe49a511de5aabce12db6f34/lib/python3.10/site-packages/wandb/apis/public.py", line 5074, in _load
    raise ValueError(
wandb.errors.CommError: Attempted to fetch artifact without alias (e.g. "<artifact_name>:v3" or "<artifact_name>:latest")